Workbook
Name ClusterList: Settings!$A$15:$A$18
Name ImpactList: Settings!$C$17:$C$20
Name MasterServerData: 'Master Servers'!$A$5:$C$200
Name MasterServerList: 'Master Servers'!$A$5:$A$200
Name MasterStatusData: 'Master Servers'!$A$5:$D$200
Name PriorityList: Settings!$A$5:$A$9
Name PriorityTable: Settings!$A$5:$D$9
Name TeamList: Settings!$A$23:$A$26

Sheet Dashboard
A1: VSPHERE SERVER PATCHING DASHBOARD
A2: Last Refreshed: | B2: =NOW() -> 46031.543
A4: PATCHING STATUS OVERVIEW
A5: Total Servers | B5: =COUNTA('NextDC M1'!A:A)-1 -> 84
A6: OVERDUE | B6: =COUNTIF('NextDC M1'!E:E,"OVERDUE") -> 26
A7: OK | B7: =COUNTIF('NextDC M1'!E:E,"OK") -> 11
A8: UNSCHEDULED | B8: =COUNTIF('NextDC M1'!E:E,"UNSCHEDULED") -> 47
A11: BY PRIORITY
A12: Priority | B12: Count | C12: Overdue
A13: 1 - Critical | B13: =COUNTIF('NextDC M1'!B:B,1) -> 18 | C13: =SUMPRODUCT(('NextDC M1'!B2:B98=1)*('NextDC M1'!C2:C98<TODAY())*ISNUMBER('NextDC M1'!C2:C98)) -> 13
A14: 2 - Medium | B14: =COUNTIF('NextDC M1'!B:B,2) -> 51 | C14: =SUMPRODUCT(('NextDC M1'!B2:B98=2)*('NextDC M1'!C2:C98<TODAY())*ISNUMBER('NextDC M1'!C2:C98)) -> 12
A15: 3 - Low/Dev | B15: =COUNTIF('NextDC M1'!B:B,3) -> 15 | C15: =SUMPRODUCT(('NextDC M1'!B2:B98=3)*('NextDC M1'!C2:C98<TODAY())*ISNUMBER('NextDC M1'!C2:C98)) -> 1
A17: CURRENT PATCHING CYCLES
A18: Priority 1 (Critical): | B18: =Settings!B4 & " days" -> Days days
A19: Priority 2 (Medium): | B19: =Settings!B5 & " days" -> 30 days
A20: Priority 3 (Low/Dev): | B20: =Settings!B6 & " days" -> 60 days
A21: (Edit in Settings sheet)
A23: QUICK ACTIONS (VBA Macros)
A24: RecordPatchDate | B24: Select server row, run to stamp today's date
A25: QuickPatchMultiple | B25: Bulk update - enter multiple server names
A26: ShowOverdueServers | B26: Display list of all OVERDUE servers
A27: GenerateEmailList | B27: Create email-ready list of overdue servers
A28: ExportPatchReport | B28: Generate printable patch status report
A29: How to run: | B29: Press Alt+F8, select macro, click Run
A32: MASTER SERVER INVENTORY
A33: Total Servers: | B33: =COUNTA('Master Servers'!A5:A200) -> 84
A34: Active: | B34: =COUNTIF('Master Servers'!D:D,"Active") -> 83
A35: Decommissioned: | B35: =COUNTIF('Master Servers'!D:D,"Decommissioned") -> 1
A36: Pending: | B36: =COUNTIF('Master Servers'!D:D,"Pending") -> 0
A38: PRIORITY SYSTEM
A39: Active Priorities: | B39: =COUNTA(Settings!A5:A9) -> 5
A40: To add priority: | B40: Settings sheet, add row to Priority Table

Sheet Master Servers
A1: MASTER SERVER LIST
A2: Add or remove servers here. Changes reflect in all dropdown lists across the workbook.
A4: Server Name | B4: Cluster | C4: Default Priority | D4: Status | E4: Date Added | F4: Notes
A5: BeaconApps | B5: NextDC M1 | C5: 2 | D5: Active | E5: 46266
A6: BeaconAppsDev | B6: NextDC M1 | C6: 2 | D6: Active | E6: 46266
A7: BeaconDB | B7: NextDC M1 | C7: 2 | D7: Active | E7: 46266
A8: BeaconDBDev | B8: NextDC M1 | C8: 2 | D8: Active | E8: 46266
A9: BeaconFOB | B9: NextDC M1 | C9: 3 | D9: Active | E9: 46266
A10: BLREPORTS | B10: NextDC M1 | C10: 2 | D10: Active | E10: 46266
A11: BLREPORTSDEV | B11: NextDC M1 | C11: 2 | D11: Active | E11: 46266
A12: BLXADIR01 | B12: NextDC M1 | C12: 2 | D12: Active | E12: 46266
A13: EEEAPP | B13: NextDC M1 | C13: 1 | D13: Active | E13: 46266
A14: EEEDB1 | B14: NextDC M1 | C14: 1 | D14: Active | E14: 46266
A15: EEEDB2 | B15: NextDC M1 | C15: 1 | D15: Active | E15: 46266
A16: EEPOSREP | B16: NextDC M1 | C16: 1 | D16: Active | E16: 46266
... A88: WSUS2019 | B88: NextDC M1 | C88: 2 | D88: Active | E88: 46266

Sheet Settings
A1: PATCHING SCHEDULE SETTINGS
A3: PRIORITY TABLE (Add rows to add priorities)
A4: Priority | B4: Days | C4: Description | D4: Server Types
A5: 1 | B5: 30 | C5: Critical | D5: SQL DBs, Production Web VMs, ERP
A6: 2 | B6: 60 | C6: Medium | D6: Application Servers, Reports
A7: 3 | B7: 90 | C7: Low/Dev | D7: Development, Test, Non-critical
A8: 4 | B8: 999
A9: 5 | B9: 999
A10: Add new rows above this line to create more priorities
A13: CLUSTER LIST
A14: Cluster Name | B14: Description
A15: NextDC M1 | B15: Primary datacenter
A16: Cluster 2 | B16: Secondary cluster
A17: Cluster 3 | B17: Development cluster
A18: Cluster 4 | B18: DR/Backup cluster
A19: Add/modify cluster names above
A21: TEAM LIST
A22: Team Name
A23: Team 1
A24: Team 2
A25: Team 3
A26: Infrastructure
A28: INSTRUCTIONS
A29: 1. Modify the green cells to adjust values
A30: 2. Add rows to Priority Table to create new priorities
A31: 3. Add cluster/team names to update dropdown lists
A32: 4. All formulas automatically update

Sheet Applications
A1: Application Name | B1: Category | C1: Associated Servers | D1: Business Owner | E1: Impact Level | F1: Notification Required | G1: Notes
A2: EEE | B2: Core Business | C2: EEEAPP, EEEDB1, EEEDB2 | E2: Critical | F2: Yes
A3: EEPOS | B3: Point of Sale | C3: EEPOSREP, EEPOSREPTEST | E3: Critical | F3: Yes
A4: GP/Dynamics | B4: ERP | C4: GPAPP, GPDB | E4: Critical | F4: Yes
A5: SlimStock | B5: Inventory | C5: BeaconDB, BeaconDBDev | E5: High | F5: Yes
A6: BDSA | B6: Reporting | C6: BLREPORTS | E6: Medium | F6: No
A7: Commercial Quote App | B7: Sales | C7: BLREPORTSDEV | E7: Medium | F7: No
A8: Trade Quote App | B8: Sales | C8: BLXADIR01 | E8: Medium | F8: No
A9: Citrix | B9: Infrastructure | C9: BLXADIR01 | E9: Critical | F9: Yes
A10: SmartConnect | B10: Integration | C10: JEDev | E10: Medium | F10: No
A11: Integration Manager | B11: Integration | C11: Management | E11: Medium | F11: No
A12: Management Reporter | B12: Reporting | C12: NDCADC | E12: Medium | F12: No
A13: PaperSave | B13: Document Management | C13: NDCADFS | E13: Low | F13: No
... A19: PIM API - External | B19: Integration | C19: EEPOSREPTEST | E19: High | F19: Yes

Sheet NextDC M1
A1: Server / VM Name | B1: Priority | C1: Next Scheduled Date | D1: Last Patch Date (DD/MM/YY) | E1: Status | F1: Days Until Due | G1: Master Status | H1: Notes | I1: Patch History (DD/MM/YY)
A2: BeaconApps | B2: =IFERROR(VLOOKUP(A2,MasterServerData,3,FALSE),"") -> 2 | C2: =IFERROR(IF(OR(B2="",NOT(ISNUMBER(B2)),NOT(ISNUMBER(D2))),"No date",D2+VLOOKUP(B2,PriorityTable,2,FALSE)),"No date") -> 45969 | D2: =IF(COUNT(I2:ZY2)=0,"No Date",MAX(I2:ZY2)) -> 45909 | E2: =IFERROR(IF(OR(B2="",C2="No date"),"UNSCHEDULED",IF(C2<TODAY(),"OVERDUE","OK")),"UNSCHEDULED") -> OVERDUE | F2: =IF(AND(ISNUMBER(C2),C2<>0),C2-TODAY(),"N/A") -> -62 | G2: =IFERROR(VLOOKUP(A2,MasterStatusData,4,FALSE),"") -> Active | I2: 45909
A3: BeaconAppsDev | B3: =IFERROR(VLOOKUP(A3,MasterServerData,3,FALSE),"") -> 2 | C3: =IFERROR(IF(OR(B3="",NOT(ISNUMBER(B3)),NOT(ISNUMBER(D3))),"No date",D3+VLOOKUP(B3,PriorityTable,2,FALSE)),"No date") -> 45970 | D3: =IF(COUNT(I3:ZY3)=0,"No Date",MAX(I3:ZY3)) -> 45910 | E3: =IFERROR(IF(OR(B3="",C3="No date"),"UNSCHEDULED",IF(C3<TODAY(),"OVERDUE","OK")),"UNSCHEDULED") -> OVERDUE | F3: =IF(AND(ISNUMBER(C3),C3<>0),C3-TODAY(),"N/A") -> -61 | G3: =IFERROR(VLOOKUP(A3,MasterStatusData,4,FALSE),"") -> Active | I3: 45910
A4: BeaconDB | B4: =IFERROR(VLOOKUP(A4,MasterServerData,3,FALSE),"") -> 2 | C4: =IFERROR(IF(OR(B4="",NOT(ISNUMBER(B4)),NOT(ISNUMBER(D4))),"No date",D4+VLOOKUP(B4,PriorityTable,2,FALSE)),"No date") -> 46026 | D4: =IF(COUNT(I4:ZY4)=0,"No Date",MAX(I4:ZY4)) -> 45966 | E4: =IFERROR(IF(OR(B4="",C4="No date"),"UNSCHEDULED",IF(C4<TODAY(),"OVERDUE","OK")),"UNSCHEDULED") -> OVERDUE | F4: =IF(AND(ISNUMBER(C4),C4<>0),C4-TODAY(),"N/A") -> -5 | G4: =IFERROR(VLOOKUP(A4,MasterStatusData,4,FALSE),"") -> Active | I4: 45966
A5: BeaconDBDev | B5: =IFERROR(VLOOKUP(A5,MasterServerData,3,FALSE),"") -> 2 | C5: =IFERROR(IF(OR(B5="",NOT(ISNUMBER(B5)),NOT(ISNUMBER(D5))),"No date",D5+VLOOKUP(B5,PriorityTable,2,FALSE)),"No date") -> 46019 | D5: =IF(COUNT(I5:ZY5)=0,"No Date",MAX(I5:ZY5)) -> 45959 | E5: =IFERROR(IF(OR(B5="",C5="No date"),"UNSCHEDULED",IF(C5<TODAY(),"OVERDUE","OK")),"UNSCHEDULED") -> OVERDUE | F5: =IF(AND(ISNUMBER(C5),C5<>0),C5-TODAY(),"N/A") -> -12 | G5: =IFERROR(VLOOKUP(A5,MasterStatusData,4,FALSE),"") -> Active | I5: 45959
A6: BeaconFOB | B6: =IFERROR(VLOOKUP(A6,MasterServerData,3,FALSE),"") -> 3 | C6: =IFERROR(IF(OR(B6="",NOT(ISNUMBER(B6)),NOT(ISNUMBER(D6))),"No date",D6+VLOOKUP(B6,PriorityTable,2,FALSE)),"No date") -> No date | D6: =IF(COUNT(I6:ZY6)=0,"No Date",MAX(I6:ZY6)) -> No Date | E6: =IFERROR(IF(OR(B6="",C6="No date"),"UNSCHEDULED",IF(C6<TODAY(),"OVERDUE","OK")),"UNSCHEDULED") -> UNSCHEDULED | F6: =IF(AND(ISNUMBER(C6),C6<>0),C6-TODAY(),"N/A") -> N/A | G6: =IFERROR(VLOOKUP(A6,MasterStatusData,4,FALSE),"") -> Active
A7: BLREPORTS | B7: =IFERROR(VLOOKUP(A7,MasterServerData,3,FALSE),"") -> 2 | C7: =IFERROR(IF(OR(B7="",NOT(ISNUMBER(B7)),NOT(ISNUMBER(D7))),"No date",D7+VLOOKUP(B7,PriorityTable,2,FALSE)),"No date") -> 46069 | D7: =IF(COUNT(I7:ZY7)=0,"No Date",MAX(I7:ZY7)) -> 46009 | E7: =IFERROR(IF(OR(B7="",C7="No date"),"UNSCHEDULED",IF(C7<TODAY(),"OVERDUE","OK")),"UNSCHEDULED") -> OK | F7: =IF(AND(ISNUMBER(C7),C7<>0),C7-TODAY(),"N/A") -> 38 | G7: =IFERROR(VLOOKUP(A7,MasterStatusData,4,FALSE),"") -> Active | I7: 46009
A8: BLREPORTSDEV | B8: =IFERROR(VLOOKUP(A8,MasterServerData,3,FALSE),"") -> 2 | C8: =IFERROR(IF(OR(B8="",NOT(ISNUMBER(B8)),NOT(ISNUMBER(D8))),"No date",D8+VLOOKUP(B8,PriorityTable,2,FALSE)),"No date") -> 46068 | D8: =IF(COUNT(I8:ZY8)=0,"No Date",MAX(I8:ZY8)) -> 46008 | E8: =IFERROR(IF(OR(B8="",C8="No date"),"UNSCHEDULED",IF(C8<TODAY(),"OVERDUE","OK")),"UNSCHEDULED") -> OK | F8: =IF(AND(ISNUMBER(C8),C8<>0),C8-TODAY(),"N/A") -> 37 | G8: =IFERROR(VLOOKUP(A8,MasterStatusData,4,FALSE),"") -> Active | I8: 46008
A9: BLXADIR01 | B9: =IFERROR(VLOOKUP(A9,MasterServerData,3,FALSE),"") -> 2 | C9: =IFERROR(IF(OR(B9="",NOT(ISNUMBER(B9)),NOT(ISNUMBER(D9))),"No date",D9+VLOOKUP(B9,PriorityTable,2,FALSE)),"No date") -> 45970 | D9: =IF(COUNT(I9:ZY9)=0,"No Date",MAX(I9:ZY9)) -> 45910 | E9: =IFERROR(IF(OR(B9="",C9="No date"),"UNSCHEDULED",IF(C9<TODAY(),"OVERDUE","OK")),"UNSCHEDULED") -> OVERDUE | F9: =IF(AND(ISNUMBER(C9),C9<>0),C9-TODAY(),"N/A") -> -61 | G9: =IFERROR(VLOOKUP(A9,MasterStatusData,4,FALSE),"") -> Active | I9: 45910
A10: EEEAPP | B10: =IFERROR(VLOOKUP(A10,MasterServerData,3,FALSE),"") -> 1 | C10: =IFERROR(IF(OR(B10="",NOT(ISNUMBER(B10)),NOT(ISNUMBER(D10))),"No date",D10+VLOOKUP(B10,PriorityTable,2,FALSE)),"No date") -> 45934 | D10: =IF(COUNT(I10:ZY10)=0,"No Date",MAX(I10:ZY10)) -> 45904 | E10: =IFERROR(IF(OR(B10="",C10="No date"),"UNSCHEDULED",IF(C10<TODAY(),"OVERDUE","OK")),"UNSCHEDULED") -> OVERDUE | F10: =IF(AND(ISNUMBER(C10),C10<>0),C10-TODAY(),"N/A") -> -97 | G10: =IFERROR(VLOOKUP(A10,MasterStatusData,4,FALSE),"") -> Active | I10: 45904
A11: EEEDB1 | B11: =IFERROR(VLOOKUP(A11,MasterServerData,3,FALSE),"") -> 1 | C11: =IFERROR(IF(OR(B11="",NOT(ISNUMBER(B11)),NOT(ISNUMBER(D11))),"No date",D11+VLOOKUP(B11,PriorityTable,2,FALSE)),"No date") -> 45934 | D11: =IF(COUNT(I11:ZY11)=0,"No Date",MAX(I11:ZY11)) -> 45904 | E11: =IFERROR(IF(OR(B11="",C11="No date"),"UNSCHEDULED",IF(C11<TODAY(),"OVERDUE","OK")),"UNSCHEDULED") -> OVERDUE | F11: =IF(AND(ISNUMBER(C11),C11<>0),C11-TODAY(),"N/A") -> -97 | G11: =IFERROR(VLOOKUP(A11,MasterStatusData,4,FALSE),"") -> Active | I11: 45904
A12: EEEDB2 | B12: =IFERROR(VLOOKUP(A12,MasterServerData,3,FALSE),"") -> 1 | C12: =IFERROR(IF(OR(B12="",NOT(ISNUMBER(B12)),NOT(ISNUMBER(D12))),"No date",D12+VLOOKUP(B12,PriorityTable,2,FALSE)),"No date") -> 45934 | D12: =IF(COUNT(I12:ZY12)=0,"No Date",MAX(I12:ZY12)) -> 45904 | E12: =IFERROR(IF(OR(B12="",C12="No date"),"UNSCHEDULED",IF(C12<TODAY(),"OVERDUE","OK")),"UNSCHEDULED") -> OVERDUE | F12: =IF(AND(ISNUMBER(C12),C12<>0),C12-TODAY(),"N/A") -> -97 | G12: =IFERROR(VLOOKUP(A12,MasterStatusData,4,FALSE),"") -> Active | I12: 45904
A13: EEPOSREP | B13: =IFERROR(VLOOKUP(A13,MasterServerData,3,FALSE),"") -> 1 | C13: =IFERROR(IF(OR(B13="",NOT(ISNUMBER(B13)),NOT(ISNUMBER(D13))),"No date",D13+VLOOKUP(B13,PriorityTable,2,FALSE)),"No date") -> 45934 | D13: =IF(COUNT(I13:ZY13)=0,"No Date",MAX(I13:ZY13)) -> 45904 | E13: =IFERROR(IF(OR(B13="",C13="No date"),"UNSCHEDULED",IF(C13<TODAY(),"OVERDUE","OK")),"UNSCHEDULED") -> OVERDUE | F13: =IF(AND(ISNUMBER(C13),C13<>0),C13-TODAY(),"N/A") -> -97 | G13: =IFERROR(VLOOKUP(A13,MasterStatusData,4,FALSE),"") -> Active | I13: 45904
A14: EEPOSREPTEST | B14: =IFERROR(VLOOKUP(A14,MasterServerData,3,FALSE),"") -> 1 | C14: =IFERROR(IF(OR(B14="",NOT(ISNUMBER(B14)),NOT(ISNUMBER(D14))),"No date",D14+VLOOKUP(B14,PriorityTable,2,FALSE)),"No date") -> 45934 | D14: =IF(COUNT(I14:ZY14)=0,"No Date",MAX(I14:ZY14)) -> 45904 | E14: =IFERROR(IF(OR(B14="",C14="No date"),"UNSCHEDULED",IF(C14<TODAY(),"OVERDUE","OK")),"UNSCHEDULED") -> OVERDUE | F14: =IF(AND(ISNUMBER(C14),C14<>0),C14-TODAY(),"N/A") -> -97 | G14: =IFERROR(VLOOKUP(A14,MasterStatusData,4,FALSE),"") -> Active | I14: 45904
A15: EETEST | B15: =IFERROR(VLOOKUP(A15,MasterServerData,3,FALSE),"") -> 1 | C15: =IFERROR(IF(OR(B15="",NOT(ISNUMBER(B15)),NOT(ISNUMBER(D15))),"No date",D15+VLOOKUP(B15,PriorityTable,2,FALSE)),"No date") -> 45958 | D15: =IF(COUNT(I15:ZY15)=0,"No Date",MAX(I15:ZY15)) -> 45928 | E15: =IFERROR(IF(OR(B15="",C15="No date"),"UNSCHEDULED",IF(C15<TODAY(),"OVERDUE","OK")),"UNSCHEDULED") -> OVERDUE | F15: =IF(AND(ISNUMBER(C15),C15<>0),C15-TODAY(),"N/A") -> -73 | G15: =IFERROR(VLOOKUP(A15,MasterStatusData,4,FALSE),"") -> Active | I15: 45928
A16: GPAPP | B16: =IFERROR(VLOOKUP(A16,MasterServerData,3,FALSE),"") -> 1 | C16: =IFERROR(IF(OR(B16="",NOT(ISNUMBER(B16)),NOT(ISNUMBER(D16))),"No date",D16+VLOOKUP(B16,PriorityTable,2,FALSE)),"No date") -> No date | D16: =IF(COUNT(I16:ZY16)=0,"No Date",MAX(I16:ZY16)) -> No Date | E16: =IFERROR(IF(OR(B16="",C16="No date"),"UNSCHEDULED",IF(C16<TODAY(),"OVERDUE","OK")),"UNSCHEDULED") -> UNSCHEDULED | F16: =IF(AND(ISNUMBER(C16),C16<>0),C16-TODAY(),"N/A") -> N/A | G16: =IFERROR(VLOOKUP(A16,MasterStatusData,4,FALSE),"") -> Active
A17: GPDB | B17: =IFERROR(VLOOKUP(A17,MasterServerData,3,FALSE),"") -> 1 | C17: =IFERROR(IF(OR(B17="",NOT(ISNUMBER(B17)),NOT(ISNUMBER(D17))),"No date",D17+VLOOKUP(B17,PriorityTable,2,FALSE)),"No date") -> No date | D17: =IF(COUNT(I17:ZY17)=0,"No Date",MAX(I17:ZY17)) -> No Date | E17: =IFERROR(IF(OR(B17="",C17="No date"),"UNSCHEDULED",IF(C17<TODAY(),"OVERDUE","OK")),"UNSCHEDULED") -> UNSCHEDULED | F17: =IF(AND(ISNUMBER(C17),C17<>0),C17-TODAY(),"N/A") -> N/A | G17: =IFERROR(VLOOKUP(A17,MasterStatusData,4,FALSE),"") -> Active
A18: IVSDB | B18: =IFERROR(VLOOKUP(A18,MasterServerData,3,FALSE),"") -> 2 | C18: =IFERROR(IF(OR(B18="",NOT(ISNUMBER(B18)),NOT(ISNUMBER(D18))),"No date",D18+VLOOKUP(B18,PriorityTable,2,FALSE)),"No date") -> 46069 | D18: =IF(COUNT(I18:ZY18)=0,"No Date",MAX(I18:ZY18)) -> 46009 | E18: =IFERROR(IF(OR(B18="",C18="No date"),"UNSCHEDULED",IF(C18<TODAY(),"OVERDUE","OK")),"UNSCHEDULED") -> OK | F18: =IF(AND(ISNUMBER(C18),C18<>0),C18-TODAY(),"N/A") -> 38 | G18: =IFERROR(VLOOKUP(A18,MasterStatusData,4,FALSE),"") -> Active | I18: 46009
A19: JEDB | B19: =IFERROR(VLOOKUP(A19,MasterServerData,3,FALSE),"") -> 2 | C19: =IFERROR(IF(OR(B19="",NOT(ISNUMBER(B19)),NOT(ISNUMBER(D19))),"No date",D19+VLOOKUP(B19,PriorityTable,2,FALSE)),"No date") -> No date | D19: =IF(COUNT(I19:ZY19)=0,"No Date",MAX(I19:ZY19)) -> No Date | E19: =IFERROR(IF(OR(B19="",C19="No date"),"UNSCHEDULED",IF(C19<TODAY(),"OVERDUE","OK")),"UNSCHEDULED") -> UNSCHEDULED | F19: =IF(AND(ISNUMBER(C19),C19<>0),C19-TODAY(),"N/A") -> N/A | G19: =IFERROR(VLOOKUP(A19,MasterStatusData,4,FALSE),"") -> Active
A20: JEDev | B20: =IFERROR(VLOOKUP(A20,MasterServerData,3,FALSE),"") -> 2 | C20: =IFERROR(IF(OR(B20="",NOT(ISNUMBER(B20)),NOT(ISNUMBER(D20))),"No date",D20+VLOOKUP(B20,PriorityTable,2,FALSE)),"No date") -> No date | D20: =IF(COUNT(I20:ZY20)=0,"No Date",MAX(I20:ZY20)) -> No Date | E20: =IFERROR(IF(OR(B20="",C20="No date"),"UNSCHEDULED",IF(C20<TODAY(),"OVERDUE","OK")),"UNSCHEDULED") -> UNSCHEDULED | F20: =IF(AND(ISNUMBER(C20),C20<>0),C20-TODAY(),"N/A") -> N/A | G20: =IFERROR(VLOOKUP(A20,MasterStatusData,4,FALSE),"") -> Active
A21: Management | B21: =IFERROR(VLOOKUP(A21,MasterServerData,3,FALSE),"") -> 2 | C21: =IFERROR(IF(OR(B21="",NOT(ISNUMBER(B21)),NOT(ISNUMBER(D21))),"No date",D21+VLOOKUP(B21,PriorityTable,2,FALSE)),"No date") -> No date | D21: =IF(COUNT(I21:ZY21)=0,"No Date",MAX(I21:ZY21)) -> No Date | E21: =IFERROR(IF(OR(B21="",C21="No date"),"UNSCHEDULED",IF(C21<TODAY(),"OVERDUE","OK")),"UNSCHEDULED") -> UNSCHEDULED | F21: =IF(AND(ISNUMBER(C21),C21<>0),C21-TODAY(),"N/A") -> N/A | G21: =IFERROR(VLOOKUP(A21,MasterStatusData,4,FALSE),"") -> Active
A22: NDCADC | B22: =IFERROR(VLOOKUP(A22,MasterServerData,3,FALSE),"") -> 2 | C22: =IFERROR(IF(OR(B22="",NOT(ISNUMBER(B22)),NOT(ISNUMBER(D22))),"No date",D22+VLOOKUP(B22,PriorityTable,2,FALSE)),"No date") -> No date | D22: =IF(COUNT(I22:ZY22)=0,"No Date",MAX(I22:ZY22)) -> No Date | E22: =IFERROR(IF(OR(B22="",C22="No date"),"UNSCHEDULED",IF(C22<TODAY(),"OVERDUE","OK")),"UNSCHEDULED") -> UNSCHEDULED | F22: =IF(AND(ISNUMBER(C22),C22<>0),C22-TODAY(),"N/A") -> N/A | G22: =IFERROR(VLOOKUP(A22,MasterStatusData,4,FALSE),"") -> Active
A23: NDCADFS | B23: =IFERROR(VLOOKUP(A23,MasterServerData,3,FALSE),"") -> 2 | C23: =IFERROR(IF(OR(B23="",NOT(ISNUMBER(B23)),NOT(ISNUMBER(D23))),"No date",D23+VLOOKUP(B23,PriorityTable,2,FALSE)),"No date") -> No date | D23: =IF(COUNT(I23:ZY23)=0,"No Date",MAX(I23:ZY23)) -> No Date | E23: =IFERROR(IF(OR(B23="",C23="No date"),"UNSCHEDULED",IF(C23<TODAY(),"OVERDUE","OK")),"UNSCHEDULED") -> UNSCHEDULED | F23: =IF(AND(ISNUMBER(C23),C23<>0),C23-TODAY(),"N/A") -> N/A | G23: =IFERROR(VLOOKUP(A23,MasterStatusData,4,FALSE),"") -> Active
A24: NDC-ADMGMT01 | B24: =IFERROR(VLOOKUP(A24,MasterServerData,3,FALSE),"") -> 2 | C24: =IFERROR(IF(OR(B24="",NOT(ISNUMBER(B24)),NOT(ISNUMBER(D24))),"No date",D24+VLOOKUP(B24,PriorityTable,2,FALSE)),"No date") -> No date | D24: =IF(COUNT(I24:ZY24)=0,"No Date",MAX(I24:ZY24)) -> No Date | E24: =IFERROR(IF(OR(B24="",C24="No date"),"UNSCHEDULED",IF(C24<TODAY(),"OVERDUE","OK")),"UNSCHEDULED") -> UNSCHEDULED | F24: =IF(AND(ISNUMBER(C24),C24<>0),C24-TODAY(),"N/A") -> N/A | G24: =IFERROR(VLOOKUP(A24,MasterStatusData,4,FALSE),"") -> Active
A25: NDC-APP01 | B25: =IFERROR(VLOOKUP(A25,MasterServerData,3,FALSE),"") -> 3 | C25: =IFERROR(IF(OR(B25="",NOT(ISNUMBER(B25)),NOT(ISNUMBER(D25))),"No date",D25+VLOOKUP(B25,PriorityTable,2,FALSE)),"No date") -> No date | D25: =IF(COUNT(I25:ZY25)=0,"No Date",MAX(I25:ZY25)) -> No Date | E25: =IFERROR(IF(OR(B25="",C25="No date"),"UNSCHEDULED",IF(C25<TODAY(),"OVERDUE","OK")),"UNSCHEDULED") -> UNSCHEDULED | F25: =IF(AND(ISNUMBER(C25),C25<>0),C25-TODAY(),"N/A") -> N/A | G25: =IFERROR(VLOOKUP(A25,MasterStatusData,4,FALSE),"") -> Active
A26: NDC-APP02 | B26: =IFERROR(VLOOKUP(A26,MasterServerData,3,FALSE),"") -> 3 | C26: =IFERROR(IF(OR(B26="",NOT(ISNUMBER(B26)),NOT(ISNUMBER(D26))),"No date",D26+VLOOKUP(B26,PriorityTable,2,FALSE)),"No date") -> No date | D26: =IF(COUNT(I26:ZY26)=0,"No Date",MAX(I26:ZY26)) -> No Date | E26: =IFERROR(IF(OR(B26="",C26="No date"),"UNSCHEDULED",IF(C26<TODAY(),"OVERDUE","OK")),"UNSCHEDULED") -> UNSCHEDULED | F26: =IF(AND(ISNUMBER(C26),C26<>0),C26-TODAY(),"N/A") -> N/A | G26: =IFERROR(VLOOKUP(A26,MasterStatusData,4,FALSE),"") -> Active
A27: NDC-BUPROXY01 | B27: =IFERROR(VLOOKUP(A27,MasterServerData,3,FALSE),"") -> 1 | C27: =IFERROR(IF(OR(B27="",NOT(ISNUMBER(B27)),NOT(ISNUMBER(D27))),"No date",D27+VLOOKUP(B27,PriorityTable,2,FALSE)),"No date") -> No date | D27: =IF(COUNT(I27:ZY27)=0,"No Date",MAX(I27:ZY27)) -> No Date | E27: =IFERROR(IF(OR(B27="",C27="No date"),"UNSCHEDULED",IF(C27<TODAY(),"OVERDUE","OK")),"UNSCHEDULED") -> UNSCHEDULED | F27: =IF(AND(ISNUMBER(C27),C27<>0),C27-TODAY(),"N/A") -> N/A | G27: =IFERROR(VLOOKUP(A27,MasterStatusData,4,FALSE),"") -> Active
A28: NDC-BUWAC01 | B28: =IFERROR(VLOOKUP(A28,MasterServerData,3,FALSE),"") -> 2 | C28: =IFERROR(IF(OR(B28="",NOT(ISNUMBER(B28)),NOT(ISNUMBER(D28))),"No date",D28+VLOOKUP(B28,PriorityTable,2,FALSE)),"No date") -> 46083 | D28: =IF(COUNT(I28:ZY28)=0,"No Date",MAX(I28:ZY28)) -> 46023 | E28: =IFERROR(IF(OR(B28="",C28="No date"),"UNSCHEDULED",IF(C28<TODAY(),"OVERDUE","OK")),"UNSCHEDULED") -> OK | F28: =IF(AND(ISNUMBER(C28),C28<>0),C28-TODAY(),"N/A") -> 52 | G28: =IFERROR(VLOOKUP(A28,MasterStatusData,4,FALSE),"") -> Active | I28: 46023
A29: NDC-BUWAC02 | B29: =IFERROR(VLOOKUP(A29,MasterServerData,3,FALSE),"") -> 2 | C29: =IFERROR(IF(OR(B29="",NOT(ISNUMBER(B29)),NOT(ISNUMBER(D29))),"No date",D29+VLOOKUP(B29,PriorityTable,2,FALSE)),"No date") -> No date | D29: =IF(COUNT(I29:ZY29)=0,"No Date",MAX(I29:ZY29)) -> No Date | E29: =IFERROR(IF(OR(B29="",C29="No date"),"UNSCHEDULED",IF(C29<TODAY(),"OVERDUE","OK")),"UNSCHEDULED") -> UNSCHEDULED | F29: =IF(AND(ISNUMBER(C29),C29<>0),C29-TODAY(),"N/A") -> N/A | G29: =IFERROR(VLOOKUP(A29,MasterStatusData,4,FALSE),"") -> Active
A30: NDC-BYB01 | B30: =IFERROR(VLOOKUP(A30,MasterServerData,3,FALSE),"") -> 2 | C30: =IFERROR(IF(OR(B30="",NOT(ISNUMBER(B30)),NOT(ISNUMBER(D30))),"No date",D30+VLOOKUP(B30,PriorityTable,2,FALSE)),"No date") -> No date | D30: =IF(COUNT(I30:ZY30)=0,"No Date",MAX(I30:ZY30)) -> No Date | E30: =IFERROR(IF(OR(B30="",C30="No date"),"UNSCHEDULED",IF(C30<TODAY(),"OVERDUE","OK")),"UNSCHEDULED") -> UNSCHEDULED | F30: =IF(AND(ISNUMBER(C30),C30<>0),C30-TODAY(),"N/A") -> N/A | G30: =IFERROR(VLOOKUP(A30,MasterStatusData,4,FALSE),"") -> Active
A31: NDC-DBMGMT01 | B31: =IFERROR(VLOOKUP(A31,MasterServerData,3,FALSE),"") -> 2 | C31: =IFERROR(IF(OR(B31="",NOT(ISNUMBER(B31)),NOT(ISNUMBER(D31))),"No date",D31+VLOOKUP(B31,PriorityTable,2,FALSE)),"No date") -> No date | D31: =IF(COUNT(I31:ZY31)=0,"No Date",MAX(I31:ZY31)) -> No Date | E31: =IFERROR(IF(OR(B31="",C31="No date"),"UNSCHEDULED",IF(C31<TODAY(),"OVERDUE","OK")),"UNSCHEDULED") -> UNSCHEDULED | F31: =IF(AND(ISNUMBER(C31),C31<>0),C31-TODAY(),"N/A") -> N/A | G31: =IFERROR(VLOOKUP(A31,MasterStatusData,4,FALSE),"") -> Active
A32: NDC-DC01 | B32: =IFERROR(VLOOKUP(A32,MasterServerData,3,FALSE),"") -> 2 | C32: =IFERROR(IF(OR(B32="",NOT(ISNUMBER(B32)),NOT(ISNUMBER(D32))),"No date",D32+VLOOKUP(B32,PriorityTable,2,FALSE)),"No date") -> No date | D32: =IF(COUNT(I32:ZY32)=0,"No Date",MAX(I32:ZY32)) -> No Date | E32: =IFERROR(IF(OR(B32="",C32="No date"),"UNSCHEDULED",IF(C32<TODAY(),"OVERDUE","OK")),"UNSCHEDULED") -> UNSCHEDULED | F32: =IF(AND(ISNUMBER(C32),C32<>0),C32-TODAY(),"N/A") -> N/A | G32: =IFERROR(VLOOKUP(A32,MasterStatusData,4,FALSE),"") -> Active
A33: NDC-DC02 | B33: =IFERROR(VLOOKUP(A33,MasterServerData,3,FALSE),"") -> 2 | C33: =IFERROR(IF(OR(B33="",NOT(ISNUMBER(B33)),NOT(ISNUMBER(D33))),"No date",D33+VLOOKUP(B33,PriorityTable,2,FALSE)),"No date") -> No date | D33: =IF(COUNT(I33:ZY33)=0,"No Date",MAX(I33:ZY33)) -> No Date | E33: =IFERROR(IF(OR(B33="",C33="No date"),"UNSCHEDULED",IF(C33<TODAY(),"OVERDUE","OK")),"UNSCHEDULED") -> UNSCHEDULED | F33: =IF(AND(ISNUMBER(C33),C33<>0),C33-TODAY(),"N/A") -> N/A | G33: =IFERROR(VLOOKUP(A33,MasterStatusData,4,FALSE),"") -> Active
A34: NDC-FILE01 | B34: =IFERROR(VLOOKUP(A34,MasterServerData,3,FALSE),"") -> 1 | C34: =IFERROR(IF(OR(B34="",NOT(ISNUMBER(B34)),NOT(ISNUMBER(D34))),"No date",D34+VLOOKUP(B34,PriorityTable,2,FALSE)),"No date") -> No date | D34: =IF(COUNT(I34:ZY34)=0,"No Date",MAX(I34:ZY34)) -> No Date | E34: =IFERROR(IF(OR(B34="",C34="No date"),"UNSCHEDULED",IF(C34<TODAY(),"OVERDUE","OK")),"UNSCHEDULED") -> UNSCHEDULED | F34: =IF(AND(ISNUMBER(C34),C34<>0),C34-TODAY(),"N/A") -> N/A | G34: =IFERROR(VLOOKUP(A34,MasterStatusData,4,FALSE),"") -> Active
A35: NDC-GP-APP | B35: =IFERROR(VLOOKUP(A35,MasterServerData,3,FALSE),"") -> 1 | C35: =IFERROR(IF(OR(B35="",NOT(ISNUMBER(B35)),NOT(ISNUMBER(D35))),"No date",D35+VLOOKUP(B35,PriorityTable,2,FALSE)),"No date") -> 45940 | D35: =IF(COUNT(I35:ZY35)=0,"No Date",MAX(I35:ZY35)) -> 45910 | E35: =IFERROR(IF(OR(B35="",C35="No date"),"UNSCHEDULED",IF(C35<TODAY(),"OVERDUE","OK")),"UNSCHEDULED") -> OVERDUE | F35: =IF(AND(ISNUMBER(C35),C35<>0),C35-TODAY(),"N/A") -> -91 | G35: =IFERROR(VLOOKUP(A35,MasterStatusData,4,FALSE),"") -> Active | I35: 45910
A36: NDC-GP-DB | B36: =IFERROR(VLOOKUP(A36,MasterServerData,3,FALSE),"") -> 1 | C36: =IFERROR(IF(OR(B36="",NOT(ISNUMBER(B36)),NOT(ISNUMBER(D36))),"No date",D36+VLOOKUP(B36,PriorityTable,2,FALSE)),"No date") -> 45940 | D36: =IF(COUNT(I36:ZY36)=0,"No Date",MAX(I36:ZY36)) -> 45910 | E36: =IFERROR(IF(OR(B36="",C36="No date"),"UNSCHEDULED",IF(C36<TODAY(),"OVERDUE","OK")),"UNSCHEDULED") -> OVERDUE | F36: =IF(AND(ISNUMBER(C36),C36<>0),C36-TODAY(),"N/A") -> -91 | G36: =IFERROR(VLOOKUP(A36,MasterStatusData,4,FALSE),"") -> Active | I36: 45910
A37: NDC-GP-DEV | B37: =IFERROR(VLOOKUP(A37,MasterServerData,3,FALSE),"") -> 1 | C37: =IFERROR(IF(OR(B37="",NOT(ISNUMBER(B37)),NOT(ISNUMBER(D37))),"No date",D37+VLOOKUP(B37,PriorityTable,2,FALSE)),"No date") -> 45935 | D37: =IF(COUNT(I37:ZY37)=0,"No Date",MAX(I37:ZY37)) -> 45905 | E37: =IFERROR(IF(OR(B37="",C37="No date"),"UNSCHEDULED",IF(C37<TODAY(),"OVERDUE","OK")),"UNSCHEDULED") -> OVERDUE | F37: =IF(AND(ISNUMBER(C37),C37<>0),C37-TODAY(),"N/A") -> -96 | G37: =IFERROR(VLOOKUP(A37,MasterStatusData,4,FALSE),"") -> Active | I37: 45905
A38: NDC-GP-STAGE | B38: =IFERROR(VLOOKUP(A38,MasterServerData,3,FALSE),"") -> 3 | C38: =IFERROR(IF(OR(B38="",NOT(ISNUMBER(B38)),NOT(ISNUMBER(D38))),"No date",D38+VLOOKUP(B38,PriorityTable,2,FALSE)),"No date") -> 45995 | D38: =IF(COUNT(I38:ZY38)=0,"No Date",MAX(I38:ZY38)) -> 45905 | E38: =IFERROR(IF(OR(B38="",C38="No date"),"UNSCHEDULED",IF(C38<TODAY(),"OVERDUE","OK")),"UNSCHEDULED") -> OVERDUE | F38: =IF(AND(ISNUMBER(C38),C38<>0),C38-TODAY(),"N/A") -> -36 | G38: =IFERROR(VLOOKUP(A38,MasterStatusData,4,FALSE),"") -> Active | I38: 45905
A39: NDC-INFRADC01 | B39: =IFERROR(VLOOKUP(A39,MasterServerData,3,FALSE),"") -> 2 | C39: =IFERROR(IF(OR(B39="",NOT(ISNUMBER(B39)),NOT(ISNUMBER(D39))),"No date",D39+VLOOKUP(B39,PriorityTable,2,FALSE)),"No date") -> No date | D39: =IF(COUNT(I39:ZY39)=0,"No Date",MAX(I39:ZY39)) -> No Date | E39: =IFERROR(IF(OR(B39="",C39="No date"),"UNSCHEDULED",IF(C39<TODAY(),"OVERDUE","OK")),"UNSCHEDULED") -> UNSCHEDULED | F39: =IF(AND(ISNUMBER(C39),C39<>0),C39-TODAY(),"N/A") -> N/A | G39: =IFERROR(VLOOKUP(A39,MasterStatusData,4,FALSE),"") -> Active
A40: NDC-INFRADC02 | B40: =IFERROR(VLOOKUP(A40,MasterServerData,3,FALSE),"") -> 2 | C40: =IFERROR(IF(OR(B40="",NOT(ISNUMBER(B40)),NOT(ISNUMBER(D40))),"No date",D40+VLOOKUP(B40,PriorityTable,2,FALSE)),"No date") -> No date | D40: =IF(COUNT(I40:ZY40)=0,"No Date",MAX(I40:ZY40)) -> No Date | E40: =IFERROR(IF(OR(B40="",C40="No date"),"UNSCHEDULED",IF(C40<TODAY(),"OVERDUE","OK")),"UNSCHEDULED") -> UNSCHEDULED | F40: =IF(AND(ISNUMBER(C40),C40<>0),C40-TODAY(),"N/A") -> N/A | G40: =IFERROR(VLOOKUP(A40,MasterStatusData,4,FALSE),"") -> Active
...

Sheet Legacy_Server list
A1: Server type | B1: Priority | C1: Frequency (months)
A2: Critical servers EG// SQL DBs and production web VMs. | B2: 1 | C2: 3
A3: Medium-risk application. | B3: 2 | C3: 6
A4: Low-risk/dev. | B4: 3 | C4: 12
A7: Server / VM Name | B7: Cluster | C7: Purpose / Applications hosted | D7: Last Patch Date (DD/MM/YY) | E7: Priority | F7: Pre-Patch Checklist | G7: Testing & Validation Contact info | H7: Broadcast emails | J7: Team | K7: Applications
A8: BeaconApps | B8: NextDC M1 | C8: App server | D8: =IFERROR(VLOOKUP(A8,'NextDC M1'!A:D,4,FALSE),"") -> 45909 | E8: 2 | G8: Team 1 | H8: TO: allbeaconanzusers@beaconlighting.com.au; CC: it@beaconlighting.com.au | J8: 1 | K8: EEE/POS related services will be affected such as:
A9: BeaconAppsDev | B9: NextDC M1 | C9: App server Testing | D9: =IFERROR(VLOOKUP(A9,'NextDC M1'!A:D,4,FALSE),"") -> 45910 | E9: 2 | F9: Notify (Team 1) | K9: - EEE
A10: BeaconDB | B10: NextDC M1 | C10: DB server | D10: =IFERROR(VLOOKUP(A10,'NextDC M1'!A:D,4,FALSE),"") -> 45966 | E10: 2 | F10: Notify (Team 1, Team 3) | G10: Team 1 | H10: TO: allbeaconanzusers@beaconlighting.com.au; CC: it@beaconlighting.com.au | K10: - EEPOS
A11: BeaconDBDev | B11: NextDC M1 | C11: DB Server Testing | D11: =IFERROR(VLOOKUP(A11,'NextDC M1'!A:D,4,FALSE),"") -> 45959 | E11: 2 | F11: Notify (Team 1) | K11: - SlimStock
A12: BeaconFOB | B12: NextDC M1 | C12: FOB Access Server (Kent Hibberd) | D12: =IFERROR(VLOOKUP(A12,'NextDC M1'!A:D,4,FALSE),"") -> No Date | E12: 3
A13: BLREPORTS | B13: NextDC M1 | C13: Reports Server | D13: =IFERROR(VLOOKUP(A13,'NextDC M1'!A:D,4,FALSE),"") -> 46009 | E13: 2 | J13: BeaconApps | K13: BDSA
A14: BLREPORTSDEV | B14: NextDC M1 | C14: Reports Server Testing | D14: =IFERROR(VLOOKUP(A14,'NextDC M1'!A:D,4,FALSE),"") -> 46008 | E14: 2 | J14: BeaonDB | K14: Commercial Quote App
A15: BLXADIR01 | B15: NextDC M1 | C15: Citrix Director (T3) | D15: =IFERROR(VLOOKUP(A15,'NextDC M1'!A:D,4,FALSE),"") -> 45910 | E15: 2 | K15: Trade Quote App
A16: EEEAPP | B16: NextDC M1 | C16: EEE | D16: =IFERROR(VLOOKUP(A16,'NextDC M1'!A:D,4,FALSE),"") -> 45904 | E16: 1 | F16: Notify (Team 1) | G16: Team 1 | H16: TO: bgsc@beaconlighting.com.au; dc@beaconlighting.com.au; allstores@beaconlighting.com.au; salesmgr@beaconlighting.com.au CC: it@beaconlighting.com.au; | K16: FDE
A17: EEEDB1 | B17: NextDC M1 | C17: EEE DB1 | D17: =IFERROR(VLOOKUP(A17,'NextDC M1'!A:D,4,FALSE),"") -> 45904 | E17: 1 | F17: Notify (Team 1) | G17: Team 1 | H17: TO: bgsc@beaconlighting.com.au; dc@beaconlighting.com.au; allstores@beaconlighting.com.au; salesmgr@beaconlighting.com.au CC: it@beaconlighting.com.au; | K17: SMA
A18: EEEDB2 | B18: NextDC M1 | C18: EEE DB2 | D18: =IFERROR(VLOOKUP(A18,'NextDC M1'!A:D,4,FALSE),"") -> 45904 | E18: 1 | F18: Notify (Team 1) | G18: Team 1 | H18: TO: bgsc@beaconlighting.com.au; dc@beaconlighting.com.au; allstores@beaconlighting.com.au; salesmgr@beaconlighting.com.au CC: it@beaconlighting.com.au; | K18: Ticketshop
A19: EEPOSREP | B19: NextDC M1 | C19: EEE POS | D19: =IFERROR(VLOOKUP(A19,'NextDC M1'!A:D,4,FALSE),"") -> 45904 | E19: 1 | F19: Notify (Team 1) | G19: Team 1 | H19: TO: bgsc@beaconlighting.com.au; dc@beaconlighting.com.au; allstores@beaconlighting.com.au; salesmgr@beaconlighting.com.au CC: it@beaconlighting.com.au; | K19: PIM API - Internal
A20: EEPOSREPTEST | B20: NextDC M1 | C20: EEE POS Testing | D20: =IFERROR(VLOOKUP(A20,'NextDC M1'!A:D,4,FALSE),"") -> 45904 | E20: 1 | F20: Notify (Team 1) | H20: N/A | K20: PIM API - External
A21: EETEST | B21: NextDC M1 | C21: EE Development Server | D21: =IFERROR(VLOOKUP(A21,'NextDC M1'!A:D,4,FALSE),"") -> 45928 | E21: 1 | F21: Notify (Team 1) | H21: N/A
A22: GPAPP | B22: NextDC M1 | C22: GP APP | D22: =IFERROR(VLOOKUP(A22,'NextDC M1'!A:D,4,FALSE),"") -> No Date | E22: 1 | F22: Approval ( Finance, Team 3) | G22: Team 3 | H22: TO: allbeaconanzusers@beaconlighting.com.au; allinternational@beaconlighting.com.au; CC: it@beaconlighting.com.au
A23: GPDB | B23: NextDC M1 | C23: GP DataBase | D23: =IFERROR(VLOOKUP(A23,'NextDC M1'!A:D,4,FALSE),"") -> No Date | E23: 1 | F23: Approval ( Finance, Team 3) | G23: Team 3 | H23: TO: allbeaconanzusers@beaconlighting.com.au; allinternational@beaconlighting.com.au; CC: it@beaconlighting.com.au
A24: IVSDB | B24: NextDC M1 | C24: IVS Database Server (T1) | D24: =IFERROR(VLOOKUP(A24,'NextDC M1'!A:D,4,FALSE),"") -> 46009 | E24: 2 | J24: 3 | K24: GP:
A25: JEDB | B25: NextDC M1 | D25: =IFERROR(VLOOKUP(A25,'NextDC M1'!A:D,4,FALSE),"") -> No Date | K25: Citrix
A26: JEDev | B26: NextDC M1 | D26: =IFERROR(VLOOKUP(A26,'NextDC M1'!A:D,4,FALSE),"") -> No Date | K26: SmartConnect
A27: Management | B27: NextDC M1 | D27: =IFERROR(VLOOKUP(A27,'NextDC M1'!A:D,4,FALSE),"") -> No Date | K27: Integration Manager
A28: NDCADC | B28: NextDC M1 | D28: =IFERROR(VLOOKUP(A28,'NextDC M1'!A:D,4,FALSE),"") -> No Date | K28: Management Reporter
A29: NDCADFS | B29: NextDC M1 | D29: =IFERROR(VLOOKUP(A29,'NextDC M1'!A:D,4,FALSE),"") -> No Date | K29: PaperSave
A30: NDC-ADMGMT01 | B30: NextDC M1 | C30: Active Directory | D30: =IFERROR(VLOOKUP(A30,'NextDC M1'!A:D,4,FALSE),"") -> No Date | E30: 2 | K30: EDI
A31: NDC-APP01 | B31: NextDC M1 | C31: Store Front | D31: =IFERROR(VLOOKUP(A31,'NextDC M1'!A:D,4,FALSE),"") -> No Date | E31: 3 | K31: Store Budget Reports
A32: NDC-APP02 | B32: NextDC M1 | C32: Diamond, Asset Mgmt | D32: =IFERROR(VLOOKUP(A32,'NextDC M1'!A:D,4,FALSE),"") -> No Date | E32: 3 | K32: Store Connect, Inventory Planning, All other applications related to GP
A33: NDC-BUPROXY01 | B33: NextDC M1 | D33: =IFERROR(VLOOKUP(A33,'NextDC M1'!A:D,4,FALSE),"") -> No Date
A34: NDC-BUWAC01 | B34: NextDC M1 | C34: NDC Domain Controller | D34: =IFERROR(VLOOKUP(A34,'NextDC M1'!A:D,4,FALSE),"") -> 46023 | E34: 2
A35: NDC-BUWAC02 | B35: NextDC M1 | C35: NDC Domain Controller | D35: =IFERROR(VLOOKUP(A35,'NextDC M1'!A:D,4,FALSE),"") -> No Date | E35: 2 | J35: 3 | K35: NDC-WMS:
A36: NDC-BYB01 | B36: NextDC M1 | D36: =IFERROR(VLOOKUP(A36,'NextDC M1'!A:D,4,FALSE),"") -> No Date | K36: Storefront (App)
A37: NDC-DBMGMT01 | B37: NextDC M1 | D37: =IFERROR(VLOOKUP(A37,'NextDC M1'!A:D,4,FALSE),"") -> No Date | K37: Warehouse Database
A38: NDC-DC01 | B38: NextDC M1 | D38: =IFERROR(VLOOKUP(A38,'NextDC M1'!A:D,4,FALSE),"") -> No Date
A39: NDC-DC02 | B39: NextDC M1 | D39: =IFERROR(VLOOKUP(A39,'NextDC M1'!A:D,4,FALSE),"") -> No Date
A40: NDC-FILE01 | B40: NextDC M1 | C40: File server | D40: =IFERROR(VLOOKUP(A40,'NextDC M1'!A:D,4,FALSE),"") -> No Date | E40: 1
A41: NDC-GP-APP | B41: NextDC M1 | C41: GP APP | D41: =IFERROR(VLOOKUP(A41,'NextDC M1'!A:D,4,FALSE),"") -> 45910 | E41: 1 | F41: Approval ( Finance, Team 3) | G41: Team 3 | H41: TO: allbeaconanzusers@beaconlighting.com.au; allinternational@beaconlighting.com.au; CC: it@beaconlighting.com.au
A42: NDC-GP-DB | B42: NextDC M1 | C42: GP DB | D42: =IFERROR(VLOOKUP(A42,'NextDC M1'!A:D,4,FALSE),"") -> 45910 | E42: 1 | F42: Approval ( Finance, Team 3) | G42: Team 3 | H42: TO: allbeaconanzusers@beaconlighting.com.au; allinternational@beaconlighting.com.au; CC: it@beaconlighting.com.au
...
